<sdf version='1.9'>
  <model name='ELM4-Chassis'>
    <pose>0 0 .5 0 0 0</pose>
    <self_collide>false</self_collide>
    <static>false</static>
    <link name="ELM4-Chassis/Base">
      <inertial>
        <mass>18.71</mass>
        <inertia>
          <ixx>0.3986</ixx>
          <ixy>0</ixy>
          <ixz>0</ixz>
          <iyy>1.092</iyy>
          <iyz>0</iyz>
          <izz>1.337</izz>
        </inertia>
      </inertial>
      <gravity>true</gravity>
      <velocity_decay/>
      <collision name="ELM4-Chassis/Base_Collision">
        <pose>0 0 .0875 0 0 0</pose>
        <geometry>
          <box>
            <size>0.8 0.389 0.171</size>
          </box>
        </geometry>
        <surface>
          <contact>
            <ode>
              <min_depth>0.001</min_depth>
              <max_vel>0</max_vel>
            </ode>
          </contact>
        </surface>
      </collision>
      <!-- <visual name="ELM4-Chassis/Base_Collision_Visual">
        <pose>0 0 .0875 0 0 0</pose>
        <geometry>
          <box>
            <size>0.8 0.389 0.171</size>
          </box>
        </geometry>
        <material>
          <diffuse>0 1 0 1</diffuse>
          <ambient>0 1 0 1</ambient>
        </material>
      </visual> -->
      <visual name="ELM4-Chassis/BaseMetal">
        <pose>0 0 0 0 0 0</pose>
        <geometry>
          <mesh>
            <scale>1 1 1</scale>
            <uri>model://ELM4-Chassis/meshes/BaseMetal.dae</uri>
          </mesh>
        </geometry>
      </visual>
      <visual name="ELM4-Chassis/BaseRubber">
        <pose>0 0 0 0 0 0</pose>
        <geometry>
          <mesh>
            <scale>1 1 1</scale>
            <uri>model://ELM4-Chassis/meshes/BaseRubber.dae</uri>
          </mesh>
        </geometry>
      </visual>
      <visual name="ELM4-Chassis/BaseYellowPlasticTop">
        <pose>0 0 0 0 0 0</pose>
        <geometry>
          <mesh>
            <scale>1 1 1</scale>
            <uri>model://ELM4-Chassis/meshes/BasePlastic.dae</uri>
          </mesh>
        </geometry>
      </visual>
      <visual name="ELM4-Chassis/BaseClearPlasticGuard">
        <pose>0 0 0 0 0 0</pose>
        <cast_shadow>0</cast_shadow>
        <transparency>.5</transparency>
        <geometry>
          <mesh>
            <scale>1 1 1</scale>
            <uri>model://ELM4-Chassis/meshes/BaseClear.dae</uri>
          </mesh>
        </geometry>
        <material>
          <diffuse>0.6 0.6 0.7 1.0</diffuse>
          <ambient>0.6 0.6 0.7 1.0</ambient>
        </material>
      </visual>
    </link>
    <link name="ELM4-Chassis/FrontLeftArm">
      <pose relative_to="ELM4-Chassis/FrontLeftArmJoint">0 0 0 0 0 0</pose>
      <inertial>
        <mass>1.16</mass>
        <inertia>
          <ixx>0.006274</ixx>
          <ixy>0.002744</ixy>
          <ixz>0</ixz>
          <iyy>0.007678</iyy>
          <iyz>0</iyz>
          <izz>0.009408</izz>
        </inertia>
      </inertial>
      <gravity>true</gravity>
      <velocity_decay/>
      <visual name="ELM4-Chassis/FrontLeftArmMetal_Visual">
        <pose>0 0 0 0 0 0</pose>
        <geometry>
          <mesh>
            <scale>1 1 1</scale>
            <uri>model://ELM4-Chassis/meshes/ArmLeftMetal.dae</uri>
          </mesh>
        </geometry>
      </visual>
      <visual name="ELM4-Chassis/FrontLeftArmPlastic_Visual">
        <pose>0 0 0 0 0 0</pose>
        <geometry>
          <mesh>
            <scale>1 1 1</scale>
            <uri>model://ELM4-Chassis/meshes/ArmLeftPlastic.dae</uri>
          </mesh>
        </geometry>
      </visual>
      <!-- <visual name="ELM4-Chassis/FrontLeftArm_Collision_Visual">
        <pose>0.055 0 -.0305 0 .505 0</pose>
        <geometry>
          <box>
            <size>.21 .075 .038</size>
          </box>
        </geometry>
        <material>
          <diffuse>0 0 1 1</diffuse>
          <ambient>0 0 1 1</ambient>
        </material>
      </visual> -->
      <collision name="ELM4-Chassis/FrontLeftArm_Collision">
        <pose>0.055 0 -.0305 0 .505 0</pose>
        <geometry>
          <box>
            <size>.21 .075 .038</size>
          </box>
        </geometry>
        <surface>
          <contact>
            <ode>
              <min_depth>0.001</min_depth>
              <max_vel>0</max_vel>
            </ode>
          </contact>
        </surface>
      </collision>
    </link>
    <link name="ELM4-Chassis/FrontLeftHubMotorWheel">
      <pose relative_to="ELM4-Chassis/FrontLeftHubMotorWheelJoint">0 0 0 0 0 0</pose>
      <inertial>
        <mass>3.854</mass>
        <inertia>
          <ixx>0.009002</ixx>
          <ixy>0.0006021</ixy>
          <ixz>0</ixz>
          <iyy>0.01313</iyy>
          <iyz>0</iyz>
          <izz>0.009003</izz>
        </inertia>
      </inertial>
      <gravity>true</gravity>
      <velocity_decay/>
      <visual name="ELM4-Chassis/FrontLeftHubMotorWheelMetal_Visual">
        <pose>0 0 0 0 0 3.14159265359</pose>
        <geometry>
          <mesh>
            <scale>1 1 1</scale>
            <uri>model://ELM4-Chassis/meshes/HubMotor.dae</uri>
          </mesh>
        </geometry>
      </visual>
      <visual name="ELM4-Chassis/FrontLeftHubMotorWheelRubber_Visual">
        <pose>0 0 0 0 0 3.14159265359</pose>
        <geometry>
          <mesh>
            <scale>1 1 1</scale>
            <uri>model://ELM4-Chassis/meshes/RubberWheel.dae</uri>
          </mesh>
        </geometry>
      </visual>
      <!-- <visual name="ELM4-Chassis/FrontLeftHubMotorWheel_Collision_Visual">
        <pose>0 0 0 1.57079632679 0 0</pose>
        <geometry>
          <cylinder>
            <radius>.108</radius>
            <length>.06</length>
          </cylinder>
        </geometry>
        <material>
          <diffuse>1 0 0 1</diffuse>
          <ambient>1 0 0 1</ambient>
        </material>
      </visual> -->
      <collision name="ELM4-Chassis/FrontLeftHubMotorWheel_Collision">
        <pose>0 0 0 1.57079632679 0 0</pose>
        <geometry>
          <cylinder>
            <radius>.108</radius>
            <length>.06</length>
          </cylinder>
        </geometry>
        <surface>
          <contact>
            <ode>
              <min_depth>0.001</min_depth>
              <max_vel>0</max_vel>
            </ode>
          </contact>
          <friction>
            <ode>
              <mu>1.0</mu>
              <mu2>0.8</mu2>
              <fdir1>1 0 0</fdir1>
            </ode>
          </friction>
        </surface>
      </collision>
    </link>
    <joint name="ELM4-Chassis/FrontLeftArmJoint" type="revolute">
      <parent>ELM4-Chassis/Base</parent>
      <child>ELM4-Chassis/FrontLeftArm</child>
      <pose relative_to="ELM4-Chassis/Base">.263 .238 .029 0 0 0</pose>
      <axis>
        <xyz>0 1 0</xyz>
        <limit>
          <lower>-0.5</lower>
          <upper>0.5</upper>
        </limit>
        <dynamics>
          <spring_reference>0</spring_reference>
          <spring_stiffness>300</spring_stiffness>
        </dynamics>
        <use_parent_model_frame>1</use_parent_model_frame>
      </axis>
    </joint>
    <joint name="ELM4-Chassis/FrontLeftHubMotorWheelJoint" type="revolute">
      <parent>ELM4-Chassis/FrontLeftArm</parent>
      <child>ELM4-Chassis/FrontLeftHubMotorWheel</child>
      <pose relative_to="ELM4-Chassis/FrontLeftArm">.11861 .095 -.07453 0 0 0</pose>
      <axis>
        <xyz>0 1 0</xyz>
        <limit>
          <lower>-1e+16</lower>
          <upper>1e+16</upper>
        </limit>
        <use_parent_model_frame>1</use_parent_model_frame>
      </axis>
    </joint>
        <link name="ELM4-Chassis/BackLeftArm">
      <pose relative_to="ELM4-Chassis/BackLeftArmJoint">0 0 0 0 0 0</pose>
      <inertial>
        <mass>1.16</mass>
        <inertia>
          <ixx>0.006274</ixx>
          <ixy>0.002744</ixy>
          <ixz>0</ixz>
          <iyy>0.007678</iyy>
          <iyz>0</iyz>
          <izz>0.009408</izz>
        </inertia>
      </inertial>
      <gravity>true</gravity>
      <velocity_decay/>
      <visual name="ELM4-Chassis/BackLeftArmMetal_Visual">
        <pose>0 0 0 0 0 0</pose>
        <geometry>
          <mesh>
            <scale>1 1 1</scale>
            <uri>model://ELM4-Chassis/meshes/ArmLeftMetal.dae</uri>
          </mesh>
        </geometry>
      </visual>
      <visual name="ELM4-Chassis/BackLeftArmPlastic_Visual">
        <pose>0 0 0 0 0 0</pose>
        <geometry>
          <mesh>
            <scale>1 1 1</scale>
            <uri>model://ELM4-Chassis/meshes/ArmLeftPlastic.dae</uri>
          </mesh>
        </geometry>
      </visual>
      <!-- <visual name="ELM4-Chassis/BackLeftArm_Collision_Visual">
        <pose>0.055 0 -.0305 0 .505 0</pose>
        <geometry>
          <box>
            <size>.21 .075 .038</size>
          </box>
        </geometry>
        <material>
          <diffuse>0 0 1 1</diffuse>
          <ambient>0 0 1 1</ambient>
        </material>
      </visual> -->
      <collision name="ELM4-Chassis/BackLeftArm_Collision">
        <pose>0.055 0 -.0305 0 .505 0</pose>
        <geometry>
          <box>
            <size>.21 .075 .038</size>
          </box>
        </geometry>
        <surface>
          <contact>
            <ode>
              <min_depth>0.001</min_depth>
              <max_vel>0</max_vel>
            </ode>
          </contact>
        </surface>
      </collision>
    </link>
    <link name="ELM4-Chassis/BackLeftHubMotorWheel">
      <pose relative_to="ELM4-Chassis/BackLeftHubMotorWheelJoint">0 0 0 0 0 0</pose>
      <inertial>
        <mass>3.854</mass>
        <inertia>
          <ixx>0.009002</ixx>
          <ixy>0.0006021</ixy>
          <ixz>0</ixz>
          <iyy>0.01313</iyy>
          <iyz>0</iyz>
          <izz>0.009003</izz>
        </inertia>
      </inertial>
      <gravity>true</gravity>
      <velocity_decay/>
      <visual name="ELM4-Chassis/BackLeftHubMotorWheelMetal_Visual">
        <pose>0 0 0 0 0 0</pose>
        <geometry>
          <mesh>
            <scale>1 1 1</scale>
            <uri>model://ELM4-Chassis/meshes/HubMotor.dae</uri>
          </mesh>
        </geometry>
      </visual>
      <visual name="ELM4-Chassis/BackLeftHubMotorWheelRubber_Visual">
        <pose>0 0 0 0 0 0</pose>
        <geometry>
          <mesh>
            <scale>1 1 1</scale>
            <uri>model://ELM4-Chassis/meshes/RubberWheel.dae</uri>
          </mesh>
        </geometry>
      </visual>
      <!-- <visual name="ELM4-Chassis/BackLeftHubMotorWheel_Collision_Visual">
        <pose>0 0 0 1.57079632679 0 0</pose>
        <geometry>
          <cylinder>
            <radius>.108</radius>
            <length>.06</length>
          </cylinder>
        </geometry>
        <material>
          <diffuse>1 0 0 1</diffuse>
          <ambient>1 0 0 1</ambient>
        </material>
      </visual> -->
      <collision name="ELM4-Chassis/BackLeftHubMotorWheel_Collision">
        <pose>0 0 0 1.57079632679 0 0</pose>
        <geometry>
          <cylinder>
            <radius>.108</radius>
            <length>.06</length>
          </cylinder>
        </geometry>
        <surface>
          <contact>
            <ode>
              <min_depth>0.001</min_depth>
              <max_vel>0</max_vel>
            </ode>
          </contact>
          <friction>
            <ode>
              <mu>1.0</mu>
              <mu2>0.8</mu2>
              <fdir1>1 0 0</fdir1>
            </ode>
          </friction>
        </surface>
      </collision>
    </link>
    <joint name="ELM4-Chassis/BackLeftArmJoint" type="revolute">
      <parent>ELM4-Chassis/Base</parent>
      <child>ELM4-Chassis/BackLeftArm</child>
      <pose relative_to="ELM4-Chassis/Base">-.263 -.238 .029 0 0 3.14159265359</pose>
      <axis>
        <xyz>0 1 0</xyz>
        <limit>
          <lower>-0.5</lower>
          <upper>0.5</upper>
        </limit>
        <dynamics>
          <spring_reference>0</spring_reference>
          <spring_stiffness>300</spring_stiffness>
        </dynamics>
        <use_parent_model_frame>1</use_parent_model_frame>
      </axis>
    </joint>
    <joint name="ELM4-Chassis/BackLeftHubMotorWheelJoint" type="revolute">
      <parent>ELM4-Chassis/BackLeftArm</parent>
      <child>ELM4-Chassis/BackLeftHubMotorWheel</child>
      <pose relative_to="ELM4-Chassis/BackLeftArm">.11861 .095 -.07453 0 0 3.14159265359</pose>
      <axis>
        <xyz>0 1 0</xyz>
        <limit>
          <lower>-1e+16</lower>
          <upper>1e+16</upper>
        </limit>
        <use_parent_model_frame>1</use_parent_model_frame>
      </axis>
    </joint>
    <link name="ELM4-Chassis/FrontRightArm">
      <pose relative_to="ELM4-Chassis/FrontRightArmJoint">0 0 0 0 0 0</pose>
      <inertial>
        <mass>1.16</mass>
        <inertia>
          <ixx>0.006274</ixx>
          <ixy>0.002744</ixy>
          <ixz>0</ixz>
          <iyy>0.007678</iyy>
          <iyz>0</iyz>
          <izz>0.009408</izz>
        </inertia>
      </inertial>
      <gravity>true</gravity>
      <velocity_decay/>
      <visual name="ELM4-Chassis/FrontRightArmMetal_Visual">
        <pose>0 0 0 0 -.017 0</pose>
        <geometry>
          <mesh>
            <scale>1 1 1</scale>
            <uri>model://ELM4-Chassis/meshes/ArmRightMetal.dae</uri>
          </mesh>
        </geometry>
      </visual>
      <visual name="ELM4-Chassis/FrontRightArmPlastic_Visual">
        <pose>0 0 0 0 -.017 0</pose>
        <geometry>
          <mesh>
            <scale>1 1 1</scale>
            <uri>model://ELM4-Chassis/meshes/ArmRightPlastic.dae</uri>
          </mesh>
        </geometry>
      </visual>
      <!-- <visual name="ELM4-Chassis/FrontRightArm_Collision_Visual">
        <pose>0.055 0 -.0305 0 .505 0</pose>
        <geometry>
          <box>
            <size>.21 .075 .038</size>
          </box>
        </geometry>
        <material>
          <diffuse>0 0 1 1</diffuse>
          <ambient>0 0 1 1</ambient>
        </material>
      </visual> -->
      <collision name="ELM4-Chassis/FrontRightArm_Collision">
        <pose>0.055 0 -.0305 0 .505 0</pose>
        <geometry>
          <box>
            <size>.21 .075 .038</size>
          </box>
        </geometry>
        <surface>
          <contact>
            <ode>
              <min_depth>0.001</min_depth>
              <max_vel>0</max_vel>
            </ode>
          </contact>
        </surface>
      </collision>
    </link>
    <link name="ELM4-Chassis/FrontRightHubMotorWheel">
      <pose relative_to="ELM4-Chassis/FrontRightHubMotorWheelJoint">0 0 0 0 0 0</pose>
      <inertial>
        <mass>3.854</mass>
        <inertia>
          <ixx>0.009002</ixx>
          <ixy>0.0006021</ixy>
          <ixz>0</ixz>
          <iyy>0.01313</iyy>
          <iyz>0</iyz>
          <izz>0.009003</izz>
        </inertia>
      </inertial>
      <gravity>true</gravity>
      <velocity_decay/>
      <visual name="ELM4-Chassis/FrontRightHubMotorWheelMetal_Visual">
        <pose>0 0 0 0 0 0</pose>
        <geometry>
          <mesh>
            <scale>1 1 1</scale>
            <uri>model://ELM4-Chassis/meshes/HubMotor.dae</uri>
          </mesh>
        </geometry>
      </visual>
      <visual name="ELM4-Chassis/FrontRightHubMotorWheelRubber_Visual">
        <pose>0 0 0 0 0 0</pose>
        <geometry>
          <mesh>
            <scale>1 1 1</scale>
            <uri>model://ELM4-Chassis/meshes/RubberWheel.dae</uri>
          </mesh>
        </geometry>
      </visual>
      <!-- <visual name="ELM4-Chassis/FrontRightHubMotorWheel_Collision_Visual">
        <pose>0 0 0 1.57079632679 0 0</pose>
        <geometry>
          <cylinder>
            <radius>.108</radius>
            <length>.06</length>
          </cylinder>
        </geometry>
        <material>
          <diffuse>1 0 0 1</diffuse>
          <ambient>1 0 0 1</ambient>
        </material>
      </visual> -->
      <collision name="ELM4-Chassis/FrontRightHubMotorWheel_Collision">
        <pose>0 0 0 1.57079632679 0 0</pose>
        <geometry>
          <cylinder>
            <radius>.108</radius>
            <length>.06</length>
          </cylinder>
        </geometry>
        <surface>
          <contact>
            <ode>
              <min_depth>0.001</min_depth>
              <max_vel>0</max_vel>
            </ode>
          </contact>
          <friction>
            <ode>
              <mu>1.0</mu>
              <mu2>0.8</mu2>
              <fdir1>1 0 0</fdir1>
            </ode>
          </friction>
        </surface>
      </collision>
    </link>
    <joint name="ELM4-Chassis/FrontRightArmJoint" type="revolute">
      <parent>ELM4-Chassis/Base</parent>
      <child>ELM4-Chassis/FrontRightArm</child>
      <pose relative_to="ELM4-Chassis/Base">.263 -.238 .029 0 0 0</pose>
      <axis>
        <xyz>0 1 0</xyz>
        <limit>
          <lower>-0.5</lower>
          <upper>0.5</upper>
        </limit>
        <dynamics>
          <spring_reference>0</spring_reference>
          <spring_stiffness>300</spring_stiffness>
        </dynamics>
        <use_parent_model_frame>1</use_parent_model_frame>
      </axis>
    </joint>
    <joint name="ELM4-Chassis/FrontRightHubMotorWheelJoint" type="revolute">
      <parent>ELM4-Chassis/FrontRightArm</parent>
      <child>ELM4-Chassis/FrontRightHubMotorWheel</child>
      <pose relative_to="ELM4-Chassis/FrontRightArm">.11861 -.095 -.07453 0 0 0</pose>
      <axis>
        <xyz>0 1 0</xyz>
        <limit>
          <lower>-1e+16</lower>
          <upper>1e+16</upper>
        </limit>
        <use_parent_model_frame>1</use_parent_model_frame>
      </axis>
    </joint>
        <link name="ELM4-Chassis/BackRightArm">
      <pose relative_to="ELM4-Chassis/BackRightArmJoint">0 0 0 0 0 0</pose>
      <inertial>
        <mass>1.16</mass>
        <inertia>
          <ixx>0.006274</ixx>
          <ixy>0.002744</ixy>
          <ixz>0</ixz>
          <iyy>0.007678</iyy>
          <iyz>0</iyz>
          <izz>0.009408</izz>
        </inertia>
      </inertial>
      <gravity>true</gravity>
      <velocity_decay/>
      <visual name="ELM4-Chassis/BackRightArmMetal_Visual">
        <pose>0 0 0 0 -.017 0</pose>
        <geometry>
          <mesh>
            <scale>1 1 1</scale>
            <uri>model://ELM4-Chassis/meshes/ArmRightMetal.dae</uri>
          </mesh>
        </geometry>
      </visual>
      <visual name="ELM4-Chassis/BackRightArmPlastic_Visual">
        <pose>0 0 0 0 -.017 0</pose>
        <geometry>
          <mesh>
            <scale>1 1 1</scale>
            <uri>model://ELM4-Chassis/meshes/ArmRightPlastic.dae</uri>
          </mesh>
        </geometry>
      </visual>
      <!-- <visual name="ELM4-Chassis/BackRightArm_Collision_Visual">
        <pose>0.055 0 -.0305 0 .505 0</pose>
        <geometry>
          <box>
            <size>.21 .075 .038</size>
          </box>
        </geometry>
        <material>
          <diffuse>0 0 1 1</diffuse>
          <ambient>0 0 1 1</ambient>
        </material>
      </visual> -->
      <collision name="ELM4-Chassis/BackRightArm_Collision">
        <pose>0.055 0 -.0305 0 .505 0</pose>
        <geometry>
          <box>
            <size>.21 .075 .038</size>
          </box>
        </geometry>
        <surface>
          <contact>
            <ode>
              <min_depth>0.001</min_depth>
              <max_vel>0</max_vel>
            </ode>
          </contact>
        </surface>
      </collision>
    </link>
    <link name="ELM4-Chassis/BackRightHubMotorWheel">
      <pose relative_to="ELM4-Chassis/BackRightHubMotorWheelJoint">0 0 0 0 0 0</pose>
      <inertial>
        <mass>3.854</mass>
        <inertia>
          <ixx>0.009002</ixx>
          <ixy>0.0006021</ixy>
          <ixz>0</ixz>
          <iyy>0.01313</iyy>
          <iyz>0</iyz>
          <izz>0.009003</izz>
        </inertia>
      </inertial>
      <gravity>true</gravity>
      <velocity_decay/>
      <visual name="ELM4-Chassis/BackRightHubMotorWheelMetal_Visual">
        <pose>0 0 0 0 0 3.14159265359</pose>
        <geometry>
          <mesh>
            <scale>1 1 1</scale>
            <uri>model://ELM4-Chassis/meshes/HubMotor.dae</uri>
          </mesh>
        </geometry>
      </visual>
      <visual name="ELM4-Chassis/BackRightHubMotorWheelRubber_Visual">
        <pose>0 0 0 0 0 3.14159265359</pose>
        <geometry>
          <mesh>
            <scale>1 1 1</scale>
            <uri>model://ELM4-Chassis/meshes/RubberWheel.dae</uri>
          </mesh>
        </geometry>
      </visual>
      <!-- <visual name="ELM4-Chassis/BackRightHubMotorWheel_Collision_Visual">
        <pose>0 0 0 1.57079632679 0 0</pose>
        <geometry>
          <cylinder>
            <radius>.108</radius>
            <length>.06</length>
          </cylinder>
        </geometry>
        <material>
          <diffuse>1 0 0 1</diffuse>
          <ambient>1 0 0 1</ambient>
        </material>
      </visual> -->
      <collision name="ELM4-Chassis/BackRightHubMotorWheel_Collision">
        <pose>0 0 0 1.57079632679 0 0</pose>
        <geometry>
          <cylinder>
            <radius>.108</radius>
            <length>.06</length>
          </cylinder>
        </geometry>
        <surface>
          <contact>
            <ode>
              <min_depth>0.001</min_depth>
              <max_vel>0</max_vel>
            </ode>
          </contact>
          <friction>
            <ode>
              <mu>1.0</mu>
              <mu2>0.8</mu2>
              <fdir1>1 0 0</fdir1>
            </ode>
          </friction>
        </surface>
      </collision>
    </link>
    <joint name="ELM4-Chassis/BackRightArmJoint" type="revolute">
      <parent>ELM4-Chassis/Base</parent>
      <child>ELM4-Chassis/BackRightArm</child>
      <pose relative_to="ELM4-Chassis/Base">-.263 .238 .029 0 0 3.14159265359</pose>
      <axis>
        <xyz>0 1 0</xyz>
        <limit>
          <lower>-0.5</lower>
          <upper>0.5</upper>
        </limit>
        <dynamics>
          <spring_reference>0</spring_reference>
          <spring_stiffness>300</spring_stiffness>
        </dynamics>
        <use_parent_model_frame>1</use_parent_model_frame>
      </axis>
    </joint>
    <joint name="ELM4-Chassis/BackRightHubMotorWheelJoint" type="revolute">
      <parent>ELM4-Chassis/BackRightArm</parent>
      <child>ELM4-Chassis/BackRightHubMotorWheel</child>
      <pose relative_to="ELM4-Chassis/BackRightArm">.11861 -.095 -.07453 0 0 3.14159265359</pose>
      <axis>
        <xyz>0 1 0</xyz>
        <limit>
          <lower>-1e+16</lower>
          <upper>1e+16</upper>
        </limit>
        <use_parent_model_frame>1</use_parent_model_frame>
      </axis>
    </joint>
    <plugin filename="libignition-gazebo-diff-drive-system.so" name="ignition::gazebo::systems::DiffDrive">
      <right_joint>ELM4-Chassis/BackLeftHubMotorWheelJoint</right_joint>
      <left_joint>ELM4-Chassis/FrontLeftHubMotorWheelJoint</left_joint>
      <left_joint>ELM4-Chassis/BackRightHubMotorWheelJoint</left_joint>
      <right_joint>ELM4-Chassis/FrontRightHubMotorWheelJoint</right_joint>
      <wheel_separation>0.667</wheel_separation>
      <wheel_radius>0.108</wheel_radius>
      <odom_publish_frequency>50</odom_publish_frequency>
      <topic>/cmd_vel</topic>
    </plugin>
  </model>
</sdf>